2025-03-06 20:58:28 | INFO | Инициализация SessionManager
2025-03-06 20:58:28 | INFO | Создан новый ключ шифрования
2025-03-06 20:58:28 | ERROR | Ошибка при проверке отложенных постов: 'utf-8' codec can't decode byte 0xff in position 0: invalid start byte
Traceback (most recent call last):

  File "C:\Users\Asus\OneDrive\Рабочий стол\Kwork\chencnik\bot.py", line 1467, in <module>
    asyncio.run(main())
    │       │   └ <function main at 0x0000016B81D07C40>
    │       └ <function run at 0x0000016BF5385EE0>
    └ <module 'asyncio' from 'C:\\Users\\Asus\\AppData\\Local\\Programs\\Python\\Python313\\Lib\\asyncio\\__init__.py'>

  File "C:\Users\Asus\AppData\Local\Programs\Python\Python313\Lib\asyncio\runners.py", line 194, in run
    return runner.run(main)
           │      │   └ <coroutine object main at 0x0000016B808822C0>
           │      └ <function Runner.run at 0x0000016BF76FEB60>
           └ <asyncio.runners.Runner object at 0x0000016B80CDA270>
  File "C:\Users\Asus\AppData\Local\Programs\Python\Python313\Lib\asyncio\runners.py", line 118, in run
    return self._loop.run_until_complete(task)
           │    │     │                  └ <Task pending name='Task-1' coro=<main() running at C:\Users\Asus\OneDrive\Рабочий стол\Kwork\chencnik\bot.py:1459> wait_for=...
           │    │     └ <function BaseEventLoop.run_until_complete at 0x0000016BF76FC720>
           │    └ <ProactorEventLoop running=True closed=False debug=False>
           └ <asyncio.runners.Runner object at 0x0000016B80CDA270>
  File "C:\Users\Asus\AppData\Local\Programs\Python\Python313\Lib\asyncio\base_events.py", line 708, in run_until_complete
    self.run_forever()
    │    └ <function BaseEventLoop.run_forever at 0x0000016BF76FC680>
    └ <ProactorEventLoop running=True closed=False debug=False>
  File "C:\Users\Asus\AppData\Local\Programs\Python\Python313\Lib\asyncio\base_events.py", line 679, in run_forever
    self._run_once()
    │    └ <function BaseEventLoop._run_once at 0x0000016BF76FE480>
    └ <ProactorEventLoop running=True closed=False debug=False>
  File "C:\Users\Asus\AppData\Local\Programs\Python\Python313\Lib\asyncio\base_events.py", line 2027, in _run_once
    handle._run()
    │      └ <function Handle._run at 0x0000016BF7625440>
    └ <Handle Task.task_wakeup()>
  File "C:\Users\Asus\AppData\Local\Programs\Python\Python313\Lib\asyncio\events.py", line 89, in _run
    self._context.run(self._callback, *self._args)
    │    │            │    │           │    └ <member '_args' of 'Handle' objects>
    │    │            │    │           └ <Handle Task.task_wakeup()>
    │    │            │    └ <member '_callback' of 'Handle' objects>
    │    │            └ <Handle Task.task_wakeup()>
    │    └ <member '_context' of 'Handle' objects>
    └ <Handle Task.task_wakeup()>

> File "C:\Users\Asus\OneDrive\Рабочий стол\Kwork\chencnik\bot.py", line 1192, in check_scheduled_posts
    posts = await Database.get_pending_posts()
                  │        └ <staticmethod(<function Database.get_pending_posts at 0x0000016BFFAF0AE0>)>
                  └ <class 'database.models.Database'>

  File "C:\Users\Asus\OneDrive\Рабочий стол\Kwork\chencnik\database\models.py", line 271, in get_pending_posts
    data = await Database._read_json(POSTS_FILE)
                 │        │          └ WindowsPath('C:/Users/Asus/OneDrive/Рабочий стол/Kwork/chencnik/database/posts.json')
                 │        └ <staticmethod(<function Database._read_json at 0x0000016BFFAD3F60>)>
                 └ <class 'database.models.Database'>

  File "C:\Users\Asus\OneDrive\Рабочий стол\Kwork\chencnik\database\models.py", line 52, in _read_json
    content = await f.read()
                    │ └ <function _make_delegate_method.<locals>.method at 0x0000016BF8541620>
                    └ <aiofiles.threadpool.text.AsyncTextIOWrapper object at 0x0000016B80CDAF90> wrapping <_io.TextIOWrapper name='C:\\Users\\Asus\...

  File "C:\Users\Asus\AppData\Local\Programs\Python\Python313\Lib\site-packages\aiofiles\threadpool\utils.py", line 43, in method
    return await self._loop.run_in_executor(self._executor, cb)
                 │    │                     │    │          └ functools.partial(<built-in method read of _io.TextIOWrapper object at 0x0000016B81CF5FC0>)
                 │    │                     │    └ None
                 │    │                     └ <aiofiles.threadpool.text.AsyncTextIOWrapper object at 0x0000016B80CDAF90> wrapping <_io.TextIOWrapper name='C:\\Users\\Asus\...
                 │    └ <property object at 0x0000016BF977B3D0>
                 └ <aiofiles.threadpool.text.AsyncTextIOWrapper object at 0x0000016B80CDAF90> wrapping <_io.TextIOWrapper name='C:\\Users\\Asus\...
  File "C:\Users\Asus\AppData\Local\Programs\Python\Python313\Lib\concurrent\futures\thread.py", line 58, in run
    result = self.fn(*self.args, **self.kwargs)
             │        │            └ None
             │        └ None
             └ None
  File "<frozen codecs>", line 325, in decode

UnicodeDecodeError: 'utf-8' codec can't decode byte 0xff in position 0: invalid start byte
