2025-03-06 21:00:08 | INFO | Инициализация SessionManager
2025-03-06 21:00:08 | DEBUG | Загружен существующий ключ шифрования
2025-03-06 21:00:37 | INFO | Попытка добавления аккаунта с номером: +998944899059
2025-03-06 21:00:37 | INFO | Отправка запроса кода для номера +998944899059
2025-03-06 21:00:37 | INFO | Создание новой сессии для номера +998944899059
2025-03-06 21:00:39 | DEBUG | Подключение к Telegram установлено для +998944899059
2025-03-06 21:00:40 | INFO | Отправка запроса кода для +998944899059
2025-03-06 21:00:40 | INFO | Код успешно отправлен для +998944899059
2025-03-06 21:00:40 | INFO | Код подтверждения запрошен для номера +998944899059
2025-03-06 21:00:44 | INFO | Получен код подтверждения для номера +998944899059
2025-03-06 21:00:44 | DEBUG | phone_code_hash для +998944899059: abc43a3530dc280e60
2025-03-06 21:00:44 | INFO | Попытка авторизации с кодом для номера +998944899059
2025-03-06 21:00:44 | INFO | Попытка авторизации по коду для +998944899059
2025-03-06 21:00:44 | DEBUG | Проверка кода для +998944899059
2025-03-06 21:00:44 | INFO | Требуется 2FA для +998944899059
2025-03-06 21:00:44 | INFO | Требуется 2FA для аккаунта +998944899059
2025-03-06 21:00:55 | INFO | Попытка авторизации по коду для +998944899059
2025-03-06 21:00:55 | DEBUG | Попытка входа с 2FA для +998944899059
2025-03-06 21:00:55 | ERROR | Критическая ошибка при авторизации +998944899059: The password (and thus its hash value) you entered is invalid (caused by CheckPasswordRequest)
Traceback (most recent call last):

  File "C:\Users\Asus\OneDrive\Рабочий стол\Kwork\chencnik\bot.py", line 1467, in <module>
    asyncio.run(main())
    │       │   └ <function main at 0x000001A41802BBA0>
    │       └ <function run at 0x000001A40C6A5EE0>
    └ <module 'asyncio' from 'C:\\Users\\Asus\\AppData\\Local\\Programs\\Python\\Python313\\Lib\\asyncio\\__init__.py'>

  File "C:\Users\Asus\AppData\Local\Programs\Python\Python313\Lib\asyncio\runners.py", line 194, in run
    return runner.run(main)
           │      │   └ <coroutine object main at 0x000001A417B9A2C0>
           │      └ <function Runner.run at 0x000001A40E9FEB60>
           └ <asyncio.runners.Runner object at 0x000001A417FF23C0>
  File "C:\Users\Asus\AppData\Local\Programs\Python\Python313\Lib\asyncio\runners.py", line 118, in run
    return self._loop.run_until_complete(task)
           │    │     │                  └ <Task pending name='Task-1' coro=<main() running at C:\Users\Asus\OneDrive\Рабочий стол\Kwork\chencnik\bot.py:1459> wait_for=...
           │    │     └ <function BaseEventLoop.run_until_complete at 0x000001A40E9FC720>
           │    └ <ProactorEventLoop running=True closed=False debug=False>
           └ <asyncio.runners.Runner object at 0x000001A417FF23C0>
  File "C:\Users\Asus\AppData\Local\Programs\Python\Python313\Lib\asyncio\base_events.py", line 708, in run_until_complete
    self.run_forever()
    │    └ <function BaseEventLoop.run_forever at 0x000001A40E9FC680>
    └ <ProactorEventLoop running=True closed=False debug=False>
  File "C:\Users\Asus\AppData\Local\Programs\Python\Python313\Lib\asyncio\base_events.py", line 679, in run_forever
    self._run_once()
    │    └ <function BaseEventLoop._run_once at 0x000001A40E9FE480>
    └ <ProactorEventLoop running=True closed=False debug=False>
  File "C:\Users\Asus\AppData\Local\Programs\Python\Python313\Lib\asyncio\base_events.py", line 2027, in _run_once
    handle._run()
    │      └ <function Handle._run at 0x000001A40E8A5440>
    └ <Handle Task.task_wakeup()>
  File "C:\Users\Asus\AppData\Local\Programs\Python\Python313\Lib\asyncio\events.py", line 89, in _run
    self._context.run(self._callback, *self._args)
    │    │            │    │           │    └ <member '_args' of 'Handle' objects>
    │    │            │    │           └ <Handle Task.task_wakeup()>
    │    │            │    └ <member '_callback' of 'Handle' objects>
    │    │            └ <Handle Task.task_wakeup()>
    │    └ <member '_context' of 'Handle' objects>
    └ <Handle Task.task_wakeup()>
  File "C:\Users\Asus\AppData\Local\Programs\Python\Python313\Lib\site-packages\aiogram\dispatcher\dispatcher.py", line 309, in _process_update
    response = await self.feed_update(bot, update, **kwargs)
                     │    │           │    │         └ {'dispatcher': <Dispatcher '0x1a417ff0d70'>, 'bots': (<aiogram.client.bot.Bot object at 0x000001A417EC3B60>,)}
                     │    │           │    └ Update(update_id=334263261, message=Message(message_id=991, date=datetime.datetime(2025, 3, 6, 16, 0, 55, tzinfo=TzInfo(UTC))...
                     │    │           └ <aiogram.client.bot.Bot object at 0x000001A417EC3B60>
                     │    └ <function Dispatcher.feed_update at 0x000001A416E13380>
                     └ <Dispatcher '0x1a417ff0d70'>
  File "C:\Users\Asus\AppData\Local\Programs\Python\Python313\Lib\site-packages\aiogram\dispatcher\dispatcher.py", line 158, in feed_update
    response = await self.update.wrap_outer_middleware(
                     │    │      └ <function TelegramEventObserver.wrap_outer_middleware at 0x000001A416E11BC0>
                     │    └ <aiogram.dispatcher.event.telegram.TelegramEventObserver object at 0x000001A418005A50>
                     └ <Dispatcher '0x1a417ff0d70'>
  File "C:\Users\Asus\AppData\Local\Programs\Python\Python313\Lib\site-packages\aiogram\dispatcher\middlewares\error.py", line 25, in __call__
    return await handler(event, data)
                 │       │      └ {'dispatcher': <Dispatcher '0x1a417ff0d70'>, 'bots': (<aiogram.client.bot.Bot object at 0x000001A417EC3B60>,), 'bot': <aiogra...
                 │       └ Update(update_id=334263261, message=Message(message_id=991, date=datetime.datetime(2025, 3, 6, 16, 0, 55, tzinfo=TzInfo(UTC))...
                 └ functools.partial(<aiogram.dispatcher.middlewares.user_context.UserContextMiddleware object at 0x000001A417FF1940>, functools...
  File "C:\Users\Asus\AppData\Local\Programs\Python\Python313\Lib\site-packages\aiogram\dispatcher\middlewares\user_context.py", line 56, in __call__
    return await handler(event, data)
                 │       │      └ {'dispatcher': <Dispatcher '0x1a417ff0d70'>, 'bots': (<aiogram.client.bot.Bot object at 0x000001A417EC3B60>,), 'bot': <aiogra...
                 │       └ Update(update_id=334263261, message=Message(message_id=991, date=datetime.datetime(2025, 3, 6, 16, 0, 55, tzinfo=TzInfo(UTC))...
                 └ functools.partial(<aiogram.fsm.middleware.FSMContextMiddleware object at 0x000001A417FF1BE0>, <function TelegramEventObserver...
  File "C:\Users\Asus\AppData\Local\Programs\Python\Python313\Lib\site-packages\aiogram\fsm\middleware.py", line 42, in __call__
    return await handler(event, data)
                 │       │      └ {'dispatcher': <Dispatcher '0x1a417ff0d70'>, 'bots': (<aiogram.client.bot.Bot object at 0x000001A417EC3B60>,), 'bot': <aiogra...
                 │       └ Update(update_id=334263261, message=Message(message_id=991, date=datetime.datetime(2025, 3, 6, 16, 0, 55, tzinfo=TzInfo(UTC))...
                 └ <function TelegramEventObserver.trigger at 0x000001A419042A20>
  File "C:\Users\Asus\AppData\Local\Programs\Python\Python313\Lib\site-packages\aiogram\dispatcher\event\telegram.py", line 121, in trigger
    return await wrapped_inner(event, kwargs)
                 │             │      └ {'dispatcher': <Dispatcher '0x1a417ff0d70'>, 'bots': (<aiogram.client.bot.Bot object at 0x000001A417EC3B60>,), 'bot': <aiogra...
                 │             └ Update(update_id=334263261, message=Message(message_id=991, date=datetime.datetime(2025, 3, 6, 16, 0, 55, tzinfo=TzInfo(UTC))...
                 └ <function CallableObject.call at 0x000001A4190428E0>
  File "C:\Users\Asus\AppData\Local\Programs\Python\Python313\Lib\site-packages\aiogram\dispatcher\event\handler.py", line 43, in call
    return await wrapped()
                 └ functools.partial(<bound method Dispatcher._listen_update of <Dispatcher '0x1a417ff0d70'>>, Update(update_id=334263261, messa...
  File "C:\Users\Asus\AppData\Local\Programs\Python\Python313\Lib\site-packages\aiogram\dispatcher\dispatcher.py", line 276, in _listen_update
    return await self.propagate_event(update_type=update_type, event=event, **kwargs)
                 │    │                           │                  │        └ {'dispatcher': <Dispatcher '0x1a417ff0d70'>, 'bots': (<aiogram.client.bot.Bot object at 0x000001A417EC3B60>,), 'bot': <aiogra...
                 │    │                           │                  └ Message(message_id=991, date=datetime.datetime(2025, 3, 6, 16, 0, 55, tzinfo=TzInfo(UTC)), chat=Chat(id=1914567632, type='pri...
                 │    │                           └ 'message'
                 │    └ <function Router.propagate_event at 0x000001A416E12980>
                 └ <Dispatcher '0x1a417ff0d70'>
  File "C:\Users\Asus\AppData\Local\Programs\Python\Python313\Lib\site-packages\aiogram\dispatcher\router.py", line 146, in propagate_event
    return await observer.wrap_outer_middleware(_wrapped, event=event, data=kwargs)
                 │        │                     │               │           └ {'dispatcher': <Dispatcher '0x1a417ff0d70'>, 'bots': (<aiogram.client.bot.Bot object at 0x000001A417EC3B60>,), 'bot': <aiogra...
                 │        │                     │               └ Message(message_id=991, date=datetime.datetime(2025, 3, 6, 16, 0, 55, tzinfo=TzInfo(UTC)), chat=Chat(id=1914567632, type='pri...
                 │        │                     └ <function Router.propagate_event.<locals>._wrapped at 0x000001A419042B60>
                 │        └ <function TelegramEventObserver.wrap_outer_middleware at 0x000001A416E11BC0>
                 └ <aiogram.dispatcher.event.telegram.TelegramEventObserver object at 0x000001A417FF0AD0>
  File "C:\Users\Asus\AppData\Local\Programs\Python\Python313\Lib\site-packages\aiogram\dispatcher\router.py", line 141, in _wrapped
    return await self._propagate_event(
                 │    └ <function Router._propagate_event at 0x000001A416E12A20>
                 └ <Dispatcher '0x1a417ff0d70'>
  File "C:\Users\Asus\AppData\Local\Programs\Python\Python313\Lib\site-packages\aiogram\dispatcher\router.py", line 166, in _propagate_event
    response = await observer.trigger(event, **kwargs)
                     │        │       │        └ {'dispatcher': <Dispatcher '0x1a417ff0d70'>, 'bots': (<aiogram.client.bot.Bot object at 0x000001A417EC3B60>,), 'bot': <aiogra...
                     │        │       └ Message(message_id=991, date=datetime.datetime(2025, 3, 6, 16, 0, 55, tzinfo=TzInfo(UTC)), chat=Chat(id=1914567632, type='pri...
                     │        └ <function TelegramEventObserver.trigger at 0x000001A416E11D00>
                     └ <aiogram.dispatcher.event.telegram.TelegramEventObserver object at 0x000001A417FF0AD0>
  File "C:\Users\Asus\AppData\Local\Programs\Python\Python313\Lib\site-packages\aiogram\dispatcher\event\telegram.py", line 121, in trigger
    return await wrapped_inner(event, kwargs)
                 │             │      └ {'dispatcher': <Dispatcher '0x1a417ff0d70'>, 'bots': (<aiogram.client.bot.Bot object at 0x000001A417EC3B60>,), 'bot': <aiogra...
                 │             └ Message(message_id=991, date=datetime.datetime(2025, 3, 6, 16, 0, 55, tzinfo=TzInfo(UTC)), chat=Chat(id=1914567632, type='pri...
                 └ <function CallableObject.call at 0x000001A419042660>
  File "C:\Users\Asus\AppData\Local\Programs\Python\Python313\Lib\site-packages\aiogram\dispatcher\event\handler.py", line 43, in call
    return await wrapped()
                 └ functools.partial(<function process_2fa at 0x000001A418029440>, Message(message_id=991, date=datetime.datetime(2025, 3, 6, 16...

  File "C:\Users\Asus\OneDrive\Рабочий стол\Kwork\chencnik\bot.py", line 217, in process_2fa
    success, result = await session_manager.auth_code(phone, None, password=password, phone_code_hash=phone_code_hash)
                            │               │         │                     │                         └ 'abc43a3530dc280e60'
                            │               │         │                     └ 'Fsv20040115sh!'
                            │               │         └ '+998944899059'
                            │               └ <function SessionManager.auth_code at 0x000001A417FE3600>
                            └ <utils.session_manager.SessionManager object at 0x000001A417FF1E80>

> File "C:\Users\Asus\OneDrive\Рабочий стол\Kwork\chencnik\utils\session_manager.py", line 118, in auth_code
    await client.sign_in(password=password)
          │      │                └ 'Fsv20040115sh!'
          │      └ <function AuthMethods.sign_in at 0x000001A417EFC360>
          └ <telethon.client.telegramclient.TelegramClient object at 0x000001A41902C6E0>

  File "C:\Users\Asus\AppData\Local\Programs\Python\Python313\Lib\site-packages\telethon\client\auth.py", line 357, in sign_in
    result = await self(request)
                   │    └ <telethon.tl.functions.auth.CheckPasswordRequest object at 0x000001A41902EA50>
                   └ <telethon.client.telegramclient.TelegramClient object at 0x000001A41902C6E0>
  File "C:\Users\Asus\AppData\Local\Programs\Python\Python313\Lib\site-packages\telethon\client\users.py", line 30, in __call__
    return await self._call(self._sender, request, ordered=ordered)
                 │    │     │    │        │                └ False
                 │    │     │    │        └ <telethon.tl.functions.auth.CheckPasswordRequest object at 0x000001A41902EA50>
                 │    │     │    └ <telethon.network.mtprotosender.MTProtoSender object at 0x000001A41902C980>
                 │    │     └ <telethon.client.telegramclient.TelegramClient object at 0x000001A41902C6E0>
                 │    └ <function UserMethods._call at 0x000001A417DAB600>
                 └ <telethon.client.telegramclient.TelegramClient object at 0x000001A41902C6E0>
  File "C:\Users\Asus\AppData\Local\Programs\Python\Python313\Lib\site-packages\telethon\client\users.py", line 87, in _call
    result = await future
                   └ <Future finished exception=PasswordHashInvalidError('The password (and thus its hash value) you entered is invalid (caused by...

telethon.errors.rpcerrorlist.PasswordHashInvalidError: The password (and thus its hash value) you entered is invalid (caused by CheckPasswordRequest)
2025-03-06 21:01:03 | INFO | Попытка добавления аккаунта с номером: +998944899059
2025-03-06 21:01:03 | INFO | Отправка запроса кода для номера +998944899059
2025-03-06 21:01:03 | INFO | Создание новой сессии для номера +998944899059
2025-03-06 21:01:05 | DEBUG | Подключение к Telegram установлено для +998944899059
2025-03-06 21:01:05 | INFO | Отправка запроса кода для +998944899059
2025-03-06 21:01:05 | INFO | Код успешно отправлен для +998944899059
2025-03-06 21:01:05 | INFO | Код подтверждения запрошен для номера +998944899059
2025-03-06 21:01:08 | INFO | Получен код подтверждения для номера +998944899059
2025-03-06 21:01:08 | DEBUG | phone_code_hash для +998944899059: 87b39d0ecae32422a4
2025-03-06 21:01:08 | INFO | Попытка авторизации с кодом для номера +998944899059
2025-03-06 21:01:08 | INFO | Попытка авторизации по коду для +998944899059
2025-03-06 21:01:08 | DEBUG | Проверка кода для +998944899059
2025-03-06 21:01:09 | INFO | Требуется 2FA для +998944899059
2025-03-06 21:01:09 | INFO | Требуется 2FA для аккаунта +998944899059
2025-03-06 21:01:12 | INFO | Попытка авторизации по коду для +998944899059
2025-03-06 21:01:12 | DEBUG | Попытка входа с 2FA для +998944899059
2025-03-06 21:01:13 | INFO | 2FA пароль подтверждён для +998944899059
2025-03-06 21:01:13 | INFO | Сессия успешно сохранена в C:\Users\Asus\OneDrive\Рабочий стол\Kwork\chencnik\sessions\user.session
2025-03-06 21:01:28 | ERROR | Ошибка при подготовке к удалению аккаунта: invalid literal for int() with base 10: 'confirm'
Traceback (most recent call last):

  File "C:\Users\Asus\OneDrive\Рабочий стол\Kwork\chencnik\bot.py", line 1467, in <module>
    asyncio.run(main())
    │       │   └ <function main at 0x000001A41802BBA0>
    │       └ <function run at 0x000001A40C6A5EE0>
    └ <module 'asyncio' from 'C:\\Users\\Asus\\AppData\\Local\\Programs\\Python\\Python313\\Lib\\asyncio\\__init__.py'>

  File "C:\Users\Asus\AppData\Local\Programs\Python\Python313\Lib\asyncio\runners.py", line 194, in run
    return runner.run(main)
           │      │   └ <coroutine object main at 0x000001A417B9A2C0>
           │      └ <function Runner.run at 0x000001A40E9FEB60>
           └ <asyncio.runners.Runner object at 0x000001A417FF23C0>
  File "C:\Users\Asus\AppData\Local\Programs\Python\Python313\Lib\asyncio\runners.py", line 118, in run
    return self._loop.run_until_complete(task)
           │    │     │                  └ <Task pending name='Task-1' coro=<main() running at C:\Users\Asus\OneDrive\Рабочий стол\Kwork\chencnik\bot.py:1459> wait_for=...
           │    │     └ <function BaseEventLoop.run_until_complete at 0x000001A40E9FC720>
           │    └ <ProactorEventLoop running=True closed=False debug=False>
           └ <asyncio.runners.Runner object at 0x000001A417FF23C0>
  File "C:\Users\Asus\AppData\Local\Programs\Python\Python313\Lib\asyncio\base_events.py", line 708, in run_until_complete
    self.run_forever()
    │    └ <function BaseEventLoop.run_forever at 0x000001A40E9FC680>
    └ <ProactorEventLoop running=True closed=False debug=False>
  File "C:\Users\Asus\AppData\Local\Programs\Python\Python313\Lib\asyncio\base_events.py", line 679, in run_forever
    self._run_once()
    │    └ <function BaseEventLoop._run_once at 0x000001A40E9FE480>
    └ <ProactorEventLoop running=True closed=False debug=False>
  File "C:\Users\Asus\AppData\Local\Programs\Python\Python313\Lib\asyncio\base_events.py", line 2027, in _run_once
    handle._run()
    │      └ <function Handle._run at 0x000001A40E8A5440>
    └ <Handle Task.task_wakeup()>
  File "C:\Users\Asus\AppData\Local\Programs\Python\Python313\Lib\asyncio\events.py", line 89, in _run
    self._context.run(self._callback, *self._args)
    │    │            │    │           │    └ <member '_args' of 'Handle' objects>
    │    │            │    │           └ <Handle Task.task_wakeup()>
    │    │            │    └ <member '_callback' of 'Handle' objects>
    │    │            └ <Handle Task.task_wakeup()>
    │    └ <member '_context' of 'Handle' objects>
    └ <Handle Task.task_wakeup()>
  File "C:\Users\Asus\AppData\Local\Programs\Python\Python313\Lib\site-packages\aiogram\dispatcher\dispatcher.py", line 309, in _process_update
    response = await self.feed_update(bot, update, **kwargs)
                     │    │           │    │         └ {'dispatcher': <Dispatcher '0x1a417ff0d70'>, 'bots': (<aiogram.client.bot.Bot object at 0x000001A417EC3B60>,)}
                     │    │           │    └ Update(update_id=334263271, message=None, edited_message=None, channel_post=None, edited_channel_post=None, business_connecti...
                     │    │           └ <aiogram.client.bot.Bot object at 0x000001A417EC3B60>
                     │    └ <function Dispatcher.feed_update at 0x000001A416E13380>
                     └ <Dispatcher '0x1a417ff0d70'>
  File "C:\Users\Asus\AppData\Local\Programs\Python\Python313\Lib\site-packages\aiogram\dispatcher\dispatcher.py", line 158, in feed_update
    response = await self.update.wrap_outer_middleware(
                     │    │      └ <function TelegramEventObserver.wrap_outer_middleware at 0x000001A416E11BC0>
                     │    └ <aiogram.dispatcher.event.telegram.TelegramEventObserver object at 0x000001A418005A50>
                     └ <Dispatcher '0x1a417ff0d70'>
  File "C:\Users\Asus\AppData\Local\Programs\Python\Python313\Lib\site-packages\aiogram\dispatcher\middlewares\error.py", line 25, in __call__
    return await handler(event, data)
                 │       │      └ {'dispatcher': <Dispatcher '0x1a417ff0d70'>, 'bots': (<aiogram.client.bot.Bot object at 0x000001A417EC3B60>,), 'bot': <aiogra...
                 │       └ Update(update_id=334263271, message=None, edited_message=None, channel_post=None, edited_channel_post=None, business_connecti...
                 └ functools.partial(<aiogram.dispatcher.middlewares.user_context.UserContextMiddleware object at 0x000001A417FF1940>, functools...
  File "C:\Users\Asus\AppData\Local\Programs\Python\Python313\Lib\site-packages\aiogram\dispatcher\middlewares\user_context.py", line 56, in __call__
    return await handler(event, data)
                 │       │      └ {'dispatcher': <Dispatcher '0x1a417ff0d70'>, 'bots': (<aiogram.client.bot.Bot object at 0x000001A417EC3B60>,), 'bot': <aiogra...
                 │       └ Update(update_id=334263271, message=None, edited_message=None, channel_post=None, edited_channel_post=None, business_connecti...
                 └ functools.partial(<aiogram.fsm.middleware.FSMContextMiddleware object at 0x000001A417FF1BE0>, <function TelegramEventObserver...
  File "C:\Users\Asus\AppData\Local\Programs\Python\Python313\Lib\site-packages\aiogram\fsm\middleware.py", line 42, in __call__
    return await handler(event, data)
                 │       │      └ {'dispatcher': <Dispatcher '0x1a417ff0d70'>, 'bots': (<aiogram.client.bot.Bot object at 0x000001A417EC3B60>,), 'bot': <aiogra...
                 │       └ Update(update_id=334263271, message=None, edited_message=None, channel_post=None, edited_channel_post=None, business_connecti...
                 └ <function TelegramEventObserver.trigger at 0x000001A4190427A0>
  File "C:\Users\Asus\AppData\Local\Programs\Python\Python313\Lib\site-packages\aiogram\dispatcher\event\telegram.py", line 121, in trigger
    return await wrapped_inner(event, kwargs)
                 │             │      └ {'dispatcher': <Dispatcher '0x1a417ff0d70'>, 'bots': (<aiogram.client.bot.Bot object at 0x000001A417EC3B60>,), 'bot': <aiogra...
                 │             └ Update(update_id=334263271, message=None, edited_message=None, channel_post=None, edited_channel_post=None, business_connecti...
                 └ <function CallableObject.call at 0x000001A419040F40>
  File "C:\Users\Asus\AppData\Local\Programs\Python\Python313\Lib\site-packages\aiogram\dispatcher\event\handler.py", line 43, in call
    return await wrapped()
                 └ functools.partial(<bound method Dispatcher._listen_update of <Dispatcher '0x1a417ff0d70'>>, Update(update_id=334263271, messa...
  File "C:\Users\Asus\AppData\Local\Programs\Python\Python313\Lib\site-packages\aiogram\dispatcher\dispatcher.py", line 276, in _listen_update
    return await self.propagate_event(update_type=update_type, event=event, **kwargs)
                 │    │                           │                  │        └ {'dispatcher': <Dispatcher '0x1a417ff0d70'>, 'bots': (<aiogram.client.bot.Bot object at 0x000001A417EC3B60>,), 'bot': <aiogra...
                 │    │                           │                  └ CallbackQuery(id='8223005369085351448', from_user=User(id=1914567632, is_bot=False, first_name='Нуритдинов Шохрух', last_name...
                 │    │                           └ 'callback_query'
                 │    └ <function Router.propagate_event at 0x000001A416E12980>
                 └ <Dispatcher '0x1a417ff0d70'>
  File "C:\Users\Asus\AppData\Local\Programs\Python\Python313\Lib\site-packages\aiogram\dispatcher\router.py", line 146, in propagate_event
    return await observer.wrap_outer_middleware(_wrapped, event=event, data=kwargs)
                 │        │                     │               │           └ {'dispatcher': <Dispatcher '0x1a417ff0d70'>, 'bots': (<aiogram.client.bot.Bot object at 0x000001A417EC3B60>,), 'bot': <aiogra...
                 │        │                     │               └ CallbackQuery(id='8223005369085351448', from_user=User(id=1914567632, is_bot=False, first_name='Нуритдинов Шохрух', last_name...
                 │        │                     └ <function Router.propagate_event.<locals>._wrapped at 0x000001A419041E40>
                 │        └ <function TelegramEventObserver.wrap_outer_middleware at 0x000001A416E11BC0>
                 └ <aiogram.dispatcher.event.telegram.TelegramEventObserver object at 0x000001A417FA59D0>
  File "C:\Users\Asus\AppData\Local\Programs\Python\Python313\Lib\site-packages\aiogram\dispatcher\router.py", line 141, in _wrapped
    return await self._propagate_event(
                 │    └ <function Router._propagate_event at 0x000001A416E12A20>
                 └ <Dispatcher '0x1a417ff0d70'>
  File "C:\Users\Asus\AppData\Local\Programs\Python\Python313\Lib\site-packages\aiogram\dispatcher\router.py", line 166, in _propagate_event
    response = await observer.trigger(event, **kwargs)
                     │        │       │        └ {'dispatcher': <Dispatcher '0x1a417ff0d70'>, 'bots': (<aiogram.client.bot.Bot object at 0x000001A417EC3B60>,), 'bot': <aiogra...
                     │        │       └ CallbackQuery(id='8223005369085351448', from_user=User(id=1914567632, is_bot=False, first_name='Нуритдинов Шохрух', last_name...
                     │        └ <function TelegramEventObserver.trigger at 0x000001A416E11D00>
                     └ <aiogram.dispatcher.event.telegram.TelegramEventObserver object at 0x000001A417FA59D0>
  File "C:\Users\Asus\AppData\Local\Programs\Python\Python313\Lib\site-packages\aiogram\dispatcher\event\telegram.py", line 121, in trigger
    return await wrapped_inner(event, kwargs)
                 │             │      └ {'dispatcher': <Dispatcher '0x1a417ff0d70'>, 'bots': (<aiogram.client.bot.Bot object at 0x000001A417EC3B60>,), 'bot': <aiogra...
                 │             └ CallbackQuery(id='8223005369085351448', from_user=User(id=1914567632, is_bot=False, first_name='Нуритдинов Шохрух', last_name...
                 └ <function CallableObject.call at 0x000001A419041D00>
  File "C:\Users\Asus\AppData\Local\Programs\Python\Python313\Lib\site-packages\aiogram\dispatcher\event\handler.py", line 43, in call
    return await wrapped()
                 └ functools.partial(<function delete_account at 0x000001A418028C20>, CallbackQuery(id='8223005369085351448', from_user=User(id=...

> File "C:\Users\Asus\OneDrive\Рабочий стол\Kwork\chencnik\bot.py", line 369, in delete_account
    account_id = int(callback.data.split('_')[2])
                     │        │    └ <method 'split' of 'str' objects>
                     │        └ 'account_delete_confirm_1'
                     └ CallbackQuery(id='8223005369085351448', from_user=User(id=1914567632, is_bot=False, first_name='Нуритдинов Шохрух', last_name...

ValueError: invalid literal for int() with base 10: 'confirm'
